[2025-08-04T08:01:47.813+0000] {local_task_job_runner.py:120} INFO - ::group::Pre task execution logs
[2025-08-04T08:01:47.942+0000] {taskinstance.py:2076} INFO - Dependencies all met for dep_context=non-requeueable deps ti=<TaskInstance: dag_aaaaa.transform_data_task3333 manual__2025-08-04T08:01:45.572500+00:00 [queued]>
[2025-08-04T08:01:47.948+0000] {taskinstance.py:2076} INFO - Dependencies all met for dep_context=requeueable deps ti=<TaskInstance: dag_aaaaa.transform_data_task3333 manual__2025-08-04T08:01:45.572500+00:00 [queued]>
[2025-08-04T08:01:47.948+0000] {taskinstance.py:2306} INFO - Starting attempt 1 of 1
[2025-08-04T08:01:47.958+0000] {taskinstance.py:2330} INFO - Executing <Task(PythonOperator): transform_data_task3333> on 2025-08-04 08:01:45.572500+00:00
[2025-08-04T08:01:47.965+0000] {standard_task_runner.py:90} INFO - Running: ['***', 'tasks', 'run', 'dag_aaaaa', 'transform_data_task3333', 'manual__2025-08-04T08:01:45.572500+00:00', '--job-id', '191', '--raw', '--subdir', 'DAGS_FOLDER/dag_generator.py', '--cfg-path', '/tmp/tmpe1uhza4o']
[2025-08-04T08:01:47.966+0000] {logging_mixin.py:188} WARNING - /home/***/.local/lib/python3.12/site-packages/***/task/task_runner/standard_task_runner.py:61 DeprecationWarning: This process (pid=10686) is multi-threaded, use of fork() may lead to deadlocks in the child.
[2025-08-04T08:01:47.967+0000] {standard_task_runner.py:91} INFO - Job 191: Subtask transform_data_task3333
[2025-08-04T08:01:47.967+0000] {standard_task_runner.py:63} INFO - Started process 10692 to run task
[2025-08-04T08:01:48.002+0000] {task_command.py:426} INFO - Running <TaskInstance: dag_aaaaa.transform_data_task3333 manual__2025-08-04T08:01:45.572500+00:00 [running]> on host 8032ab58e64f
[2025-08-04T08:01:48.066+0000] {taskinstance.py:2648} INFO - Exporting env vars: AIRFLOW_CTX_DAG_OWNER='***' AIRFLOW_CTX_DAG_ID='dag_aaaaa' AIRFLOW_CTX_TASK_ID='transform_data_task3333' AIRFLOW_CTX_EXECUTION_DATE='2025-08-04T08:01:45.572500+00:00' AIRFLOW_CTX_TRY_NUMBER='1' AIRFLOW_CTX_DAG_RUN_ID='manual__2025-08-04T08:01:45.572500+00:00'
[2025-08-04T08:01:48.067+0000] {taskinstance.py:430} INFO - ::endgroup::
[2025-08-04T08:01:48.074+0000] {__init__.py:118} INFO - 執行 transform_data (資料轉換層)
[2025-08-04T08:01:48.075+0000] {__init__.py:58} INFO - _get_upstream_output_path 上游任務: {'extract_data_task'}
[2025-08-04T08:01:48.075+0000] {__init__.py:74} INFO - 任務 'transform_data_task3333' 從單一上游 'extract_data_task' 拉取資料
[2025-08-04T08:01:48.083+0000] {__init__.py:76} INFO - 拉取到的 redis_key: ***_data:dag_aaaaa.extract_data_task
[2025-08-04T08:01:48.084+0000] {__init__.py:177} ERROR - transform_data 發生例外: Redis 無資料，key=***_data:dag_aaaaa.extract_data_task
[2025-08-04T08:01:48.084+0000] {taskinstance.py:441} INFO - ::group::Post task execution logs
[2025-08-04T08:01:48.084+0000] {taskinstance.py:2905} ERROR - Task failed with exception
Traceback (most recent call last):
  File "/home/airflow/.local/lib/python3.12/site-packages/airflow/models/taskinstance.py", line 465, in _execute_task
    result = _execute_callable(context=context, **execute_callable_kwargs)
             ^^^^^^^^^^^^^^^^^^^^^^^^^^^^^^^^^^^^^^^^^^^^^^^^^^^^^^^^^^^^^
  File "/home/airflow/.local/lib/python3.12/site-packages/airflow/models/taskinstance.py", line 432, in _execute_callable
    return execute_callable(context=context, **execute_callable_kwargs)
           ^^^^^^^^^^^^^^^^^^^^^^^^^^^^^^^^^^^^^^^^^^^^^^^^^^^^^^^^^^^^
  File "/home/airflow/.local/lib/python3.12/site-packages/airflow/models/baseoperator.py", line 401, in wrapper
    return func(self, *args, **kwargs)
           ^^^^^^^^^^^^^^^^^^^^^^^^^^^
  File "/home/airflow/.local/lib/python3.12/site-packages/airflow/operators/python.py", line 235, in execute
    return_value = self.execute_callable()
                   ^^^^^^^^^^^^^^^^^^^^^^^
  File "/home/airflow/.local/lib/python3.12/site-packages/airflow/operators/python.py", line 252, in execute_callable
    return self.python_callable(*self.op_args, **self.op_kwargs)
           ^^^^^^^^^^^^^^^^^^^^^^^^^^^^^^^^^^^^^^^^^^^^^^^^^^^^^
  File "/opt/airflow/dags/processor/__init__.py", line 137, in transform_data
    raise RuntimeError(f"Redis 無資料，key={upstream_redis_keys}")
RuntimeError: Redis 無資料，key=***_data:dag_aaaaa.extract_data_task
[2025-08-04T08:01:48.090+0000] {taskinstance.py:1206} INFO - Marking task as FAILED. dag_id=dag_aaaaa, task_id=transform_data_task3333, run_id=manual__2025-08-04T08:01:45.572500+00:00, execution_date=20250804T080145, start_date=20250804T080147, end_date=20250804T080148
[2025-08-04T08:01:48.104+0000] {standard_task_runner.py:110} ERROR - Failed to execute job 191 for task transform_data_task3333 (Redis 無資料，key=***_data:dag_aaaaa.extract_data_task; 10692)
[2025-08-04T08:01:48.140+0000] {local_task_job_runner.py:240} INFO - Task exited with return code 1
[2025-08-04T08:01:48.164+0000] {taskinstance.py:3503} INFO - 0 downstream tasks scheduled from follow-on schedule check
[2025-08-04T08:01:48.166+0000] {local_task_job_runner.py:222} INFO - ::endgroup::
