[2025-07-30T08:31:22.768+0000] {local_task_job_runner.py:120} INFO - ::group::Pre task execution logs
[2025-07-30T08:31:22.807+0000] {taskinstance.py:2076} INFO - Dependencies all met for dep_context=non-requeueable deps ti=<TaskInstance: dag_qaaaaqqqqqqqq.transform_data_task333 scheduled__2025-06-25T00:00:00+00:00 [queued]>
[2025-07-30T08:31:22.818+0000] {taskinstance.py:2076} INFO - Dependencies all met for dep_context=requeueable deps ti=<TaskInstance: dag_qaaaaqqqqqqqq.transform_data_task333 scheduled__2025-06-25T00:00:00+00:00 [queued]>
[2025-07-30T08:31:22.818+0000] {taskinstance.py:2306} INFO - Starting attempt 1 of 1
[2025-07-30T08:31:22.945+0000] {taskinstance.py:2330} INFO - Executing <Task(PythonOperator): transform_data_task333> on 2025-06-25 00:00:00+00:00
[2025-07-30T08:31:22.954+0000] {logging_mixin.py:188} WARNING - /home/***/.local/lib/python3.12/site-packages/***/task/task_runner/standard_task_runner.py:61 DeprecationWarning: This process (pid=6222) is multi-threaded, use of fork() may lead to deadlocks in the child.
[2025-07-30T08:31:22.954+0000] {standard_task_runner.py:63} INFO - Started process 6224 to run task
[2025-07-30T08:31:22.955+0000] {standard_task_runner.py:90} INFO - Running: ['***', 'tasks', 'run', 'dag_qaaaaqqqqqqqq', 'transform_data_task333', 'scheduled__2025-06-25T00:00:00+00:00', '--job-id', '39', '--raw', '--subdir', 'DAGS_FOLDER/dag_generator_python.py', '--cfg-path', '/tmp/tmppxti01ym']
[2025-07-30T08:31:22.957+0000] {standard_task_runner.py:91} INFO - Job 39: Subtask transform_data_task333
[2025-07-30T08:31:23.002+0000] {task_command.py:426} INFO - Running <TaskInstance: dag_qaaaaqqqqqqqq.transform_data_task333 scheduled__2025-06-25T00:00:00+00:00 [running]> on host 14614e29d246
[2025-07-30T08:31:23.086+0000] {taskinstance.py:2648} INFO - Exporting env vars: AIRFLOW_CTX_DAG_OWNER='***' AIRFLOW_CTX_DAG_ID='dag_qaaaaqqqqqqqq' AIRFLOW_CTX_TASK_ID='transform_data_task333' AIRFLOW_CTX_EXECUTION_DATE='2025-06-25T00:00:00+00:00' AIRFLOW_CTX_TRY_NUMBER='1' AIRFLOW_CTX_DAG_RUN_ID='scheduled__2025-06-25T00:00:00+00:00'
[2025-07-30T08:31:23.087+0000] {taskinstance.py:430} INFO - ::endgroup::
[2025-07-30T08:31:23.101+0000] {logging_mixin.py:188} INFO - 測試轉換層
[2025-07-30T08:31:23.101+0000] {logging_mixin.py:188} INFO - aaaaaaaaa:{'extract_data_task'}
[2025-07-30T08:31:23.102+0000] {logging_mixin.py:188} INFO - 任務 'transform_data_task333' 正在從上游 'extract_data_task' 拉取資料...
[2025-07-30T08:31:23.111+0000] {logging_mixin.py:188} INFO - bbbbbbb:***_data:extract_data_task
[2025-07-30T08:31:23.111+0000] {logging_mixin.py:188} INFO - ***_data:extract_data_task
[2025-07-30T08:31:23.111+0000] {logging_mixin.py:188} INFO - 2222222222222222222222222222222
[2025-07-30T08:31:23.111+0000] {logging_mixin.py:188} INFO - ***_data:***_data:extract_data_task
[2025-07-30T08:31:23.112+0000] {logging_mixin.py:188} INFO - Fetching data from Redis key: ***_data:***_data:extract_data_task
[2025-07-30T08:31:23.113+0000] {taskinstance.py:441} INFO - ::group::Post task execution logs
[2025-07-30T08:31:23.113+0000] {taskinstance.py:2905} ERROR - Task failed with exception
Traceback (most recent call last):
  File "/home/airflow/.local/lib/python3.12/site-packages/airflow/models/taskinstance.py", line 465, in _execute_task
    result = _execute_callable(context=context, **execute_callable_kwargs)
             ^^^^^^^^^^^^^^^^^^^^^^^^^^^^^^^^^^^^^^^^^^^^^^^^^^^^^^^^^^^^^
  File "/home/airflow/.local/lib/python3.12/site-packages/airflow/models/taskinstance.py", line 432, in _execute_callable
    return execute_callable(context=context, **execute_callable_kwargs)
           ^^^^^^^^^^^^^^^^^^^^^^^^^^^^^^^^^^^^^^^^^^^^^^^^^^^^^^^^^^^^
  File "/home/airflow/.local/lib/python3.12/site-packages/airflow/models/baseoperator.py", line 401, in wrapper
    return func(self, *args, **kwargs)
           ^^^^^^^^^^^^^^^^^^^^^^^^^^^
  File "/home/airflow/.local/lib/python3.12/site-packages/airflow/operators/python.py", line 235, in execute
    return_value = self.execute_callable()
                   ^^^^^^^^^^^^^^^^^^^^^^^
  File "/home/airflow/.local/lib/python3.12/site-packages/airflow/operators/python.py", line 252, in execute_callable
    return self.python_callable(*self.op_args, **self.op_kwargs)
           ^^^^^^^^^^^^^^^^^^^^^^^^^^^^^^^^^^^^^^^^^^^^^^^^^^^^^
  File "/opt/airflow/dags/processor/__init__.py", line 85, in transform_data
    raise RuntimeError(f"Redis 無資料，key={redis_key}")
RuntimeError: Redis 無資料，key=***_data:***_data:extract_data_task
[2025-07-30T08:31:23.122+0000] {taskinstance.py:1206} INFO - Marking task as FAILED. dag_id=dag_qaaaaqqqqqqqq, task_id=transform_data_task333, run_id=scheduled__2025-06-25T00:00:00+00:00, execution_date=20250625T000000, start_date=20250730T083122, end_date=20250730T083123
[2025-07-30T08:31:23.137+0000] {standard_task_runner.py:110} ERROR - Failed to execute job 39 for task transform_data_task333 (Redis 無資料，key=***_data:***_data:extract_data_task; 6224)
[2025-07-30T08:31:23.168+0000] {local_task_job_runner.py:240} INFO - Task exited with return code 1
[2025-07-30T08:31:23.190+0000] {taskinstance.py:3503} INFO - 0 downstream tasks scheduled from follow-on schedule check
[2025-07-30T08:31:23.194+0000] {local_task_job_runner.py:222} INFO - ::endgroup::
