[2025-07-28T12:49:54.614+0000] {local_task_job_runner.py:120} INFO - ::group::Pre task execution logs
[2025-07-28T12:49:54.810+0000] {taskinstance.py:2076} INFO - Dependencies all met for dep_context=non-requeueable deps ti=<TaskInstance: dag_qqqqqqqqqqqqqqq.transform_data_task scheduled__2025-06-25T00:00:00+00:00 [queued]>
[2025-07-28T12:49:54.821+0000] {taskinstance.py:2076} INFO - Dependencies all met for dep_context=requeueable deps ti=<TaskInstance: dag_qqqqqqqqqqqqqqq.transform_data_task scheduled__2025-06-25T00:00:00+00:00 [queued]>
[2025-07-28T12:49:54.822+0000] {taskinstance.py:2306} INFO - Starting attempt 1 of 1
[2025-07-28T12:49:54.836+0000] {taskinstance.py:2330} INFO - Executing <Task(PythonOperator): transform_data_task> on 2025-06-25 00:00:00+00:00
[2025-07-28T12:49:54.850+0000] {logging_mixin.py:188} WARNING - /home/***/.local/lib/python3.12/site-packages/***/task/task_runner/standard_task_runner.py:61 DeprecationWarning: This process (pid=4014) is multi-threaded, use of fork() may lead to deadlocks in the child.
[2025-07-28T12:49:54.851+0000] {standard_task_runner.py:63} INFO - Started process 4016 to run task
[2025-07-28T12:49:54.848+0000] {standard_task_runner.py:90} INFO - Running: ['***', 'tasks', 'run', 'dag_qqqqqqqqqqqqqqq', 'transform_data_task', 'scheduled__2025-06-25T00:00:00+00:00', '--job-id', '52', '--raw', '--subdir', 'DAGS_FOLDER/dag_generator_python.py', '--cfg-path', '/tmp/tmpn18l_uy9']
[2025-07-28T12:49:54.851+0000] {standard_task_runner.py:91} INFO - Job 52: Subtask transform_data_task
[2025-07-28T12:49:54.938+0000] {task_command.py:426} INFO - Running <TaskInstance: dag_qqqqqqqqqqqqqqq.transform_data_task scheduled__2025-06-25T00:00:00+00:00 [running]> on host 1171f9d2ced8
[2025-07-28T12:49:55.046+0000] {taskinstance.py:2648} INFO - Exporting env vars: AIRFLOW_CTX_DAG_OWNER='***' AIRFLOW_CTX_DAG_ID='dag_qqqqqqqqqqqqqqq' AIRFLOW_CTX_TASK_ID='transform_data_task' AIRFLOW_CTX_EXECUTION_DATE='2025-06-25T00:00:00+00:00' AIRFLOW_CTX_TRY_NUMBER='1' AIRFLOW_CTX_DAG_RUN_ID='scheduled__2025-06-25T00:00:00+00:00'
[2025-07-28T12:49:55.047+0000] {taskinstance.py:430} INFO - ::endgroup::
[2025-07-28T12:49:55.060+0000] {logging_mixin.py:188} INFO - Fetching data from Redis key: ***_data:dag_qqqqqqqqqqqqqqq
[2025-07-28T12:49:55.083+0000] {logging_mixin.py:188} INFO - Applying algorithm 'aggregate_product_data' from module 'processor.transform.algos_1'
[2025-07-28T12:49:55.083+0000] {taskinstance.py:441} INFO - ::group::Post task execution logs
[2025-07-28T12:49:55.083+0000] {taskinstance.py:2905} ERROR - Task failed with exception
Traceback (most recent call last):
  File "/home/airflow/.local/lib/python3.12/site-packages/pandas/core/indexes/base.py", line 3791, in get_loc
    return self._engine.get_loc(casted_key)
           ^^^^^^^^^^^^^^^^^^^^^^^^^^^^^^^^
  File "index.pyx", line 152, in pandas._libs.index.IndexEngine.get_loc
  File "index.pyx", line 181, in pandas._libs.index.IndexEngine.get_loc
  File "pandas/_libs/hashtable_class_helper.pxi", line 7080, in pandas._libs.hashtable.PyObjectHashTable.get_item
  File "pandas/_libs/hashtable_class_helper.pxi", line 7088, in pandas._libs.hashtable.PyObjectHashTable.get_item
KeyError: 'quantity'

The above exception was the direct cause of the following exception:

Traceback (most recent call last):
  File "/home/airflow/.local/lib/python3.12/site-packages/airflow/models/taskinstance.py", line 465, in _execute_task
    result = _execute_callable(context=context, **execute_callable_kwargs)
             ^^^^^^^^^^^^^^^^^^^^^^^^^^^^^^^^^^^^^^^^^^^^^^^^^^^^^^^^^^^^^
  File "/home/airflow/.local/lib/python3.12/site-packages/airflow/models/taskinstance.py", line 432, in _execute_callable
    return execute_callable(context=context, **execute_callable_kwargs)
           ^^^^^^^^^^^^^^^^^^^^^^^^^^^^^^^^^^^^^^^^^^^^^^^^^^^^^^^^^^^^
  File "/home/airflow/.local/lib/python3.12/site-packages/airflow/models/baseoperator.py", line 401, in wrapper
    return func(self, *args, **kwargs)
           ^^^^^^^^^^^^^^^^^^^^^^^^^^^
  File "/home/airflow/.local/lib/python3.12/site-packages/airflow/operators/python.py", line 235, in execute
    return_value = self.execute_callable()
                   ^^^^^^^^^^^^^^^^^^^^^^^
  File "/home/airflow/.local/lib/python3.12/site-packages/airflow/operators/python.py", line 252, in execute_callable
    return self.python_callable(*self.op_args, **self.op_kwargs)
           ^^^^^^^^^^^^^^^^^^^^^^^^^^^^^^^^^^^^^^^^^^^^^^^^^^^^^
  File "/opt/airflow/dags/processor/__init__.py", line 43, in transform_data
    processed_df = func(df, **algo_kwargs)
                   ^^^^^^^^^^^^^^^^^^^^^^^
  File "/opt/airflow/dags/processor/transform/algos_1.py", line 4, in aggregate_product_data
    df['total_price'] = df['quantity'] * df['price'] * multiplier
                        ~~^^^^^^^^^^^^
  File "/home/airflow/.local/lib/python3.12/site-packages/pandas/core/frame.py", line 3893, in __getitem__
    indexer = self.columns.get_loc(key)
              ^^^^^^^^^^^^^^^^^^^^^^^^^
  File "/home/airflow/.local/lib/python3.12/site-packages/pandas/core/indexes/base.py", line 3798, in get_loc
    raise KeyError(key) from err
KeyError: 'quantity'
[2025-07-28T12:49:55.098+0000] {taskinstance.py:1206} INFO - Marking task as FAILED. dag_id=dag_qqqqqqqqqqqqqqq, task_id=transform_data_task, run_id=scheduled__2025-06-25T00:00:00+00:00, execution_date=20250625T000000, start_date=20250728T124954, end_date=20250728T124955
[2025-07-28T12:49:55.111+0000] {standard_task_runner.py:110} ERROR - Failed to execute job 52 for task transform_data_task ('quantity'; 4016)
[2025-07-28T12:49:55.145+0000] {local_task_job_runner.py:240} INFO - Task exited with return code 1
[2025-07-28T12:49:55.185+0000] {taskinstance.py:3503} INFO - 0 downstream tasks scheduled from follow-on schedule check
[2025-07-28T12:49:55.191+0000] {local_task_job_runner.py:222} INFO - ::endgroup::
