[2025-07-28T07:10:57.467+0000] {local_task_job_runner.py:120} INFO - ::group::Pre task execution logs
[2025-07-28T07:10:57.489+0000] {taskinstance.py:2076} INFO - Dependencies all met for dep_context=non-requeueable deps ti=<TaskInstance: dag_32222222223.transform_data_task scheduled__2025-06-25T00:00:00+00:00 [queued]>
[2025-07-28T07:10:57.499+0000] {taskinstance.py:2076} INFO - Dependencies all met for dep_context=requeueable deps ti=<TaskInstance: dag_32222222223.transform_data_task scheduled__2025-06-25T00:00:00+00:00 [queued]>
[2025-07-28T07:10:57.499+0000] {taskinstance.py:2306} INFO - Starting attempt 1 of 1
[2025-07-28T07:10:57.516+0000] {taskinstance.py:2330} INFO - Executing <Task(PythonOperator): transform_data_task> on 2025-06-25 00:00:00+00:00
[2025-07-28T07:10:57.527+0000] {standard_task_runner.py:90} INFO - Running: ['***', 'tasks', 'run', 'dag_32222222223', 'transform_data_task', 'scheduled__2025-06-25T00:00:00+00:00', '--job-id', '21', '--raw', '--subdir', 'DAGS_FOLDER/dag_generator_python.py', '--cfg-path', '/tmp/tmpz8_4z_5a']
[2025-07-28T07:10:57.529+0000] {standard_task_runner.py:91} INFO - Job 21: Subtask transform_data_task
[2025-07-28T07:10:57.660+0000] {logging_mixin.py:188} WARNING - /home/***/.local/lib/python3.12/site-packages/***/task/task_runner/standard_task_runner.py:61 DeprecationWarning: This process (pid=7869) is multi-threaded, use of fork() may lead to deadlocks in the child.
[2025-07-28T07:10:57.660+0000] {standard_task_runner.py:63} INFO - Started process 7871 to run task
[2025-07-28T07:10:57.711+0000] {task_command.py:426} INFO - Running <TaskInstance: dag_32222222223.transform_data_task scheduled__2025-06-25T00:00:00+00:00 [running]> on host 1171f9d2ced8
[2025-07-28T07:10:57.856+0000] {taskinstance.py:2648} INFO - Exporting env vars: AIRFLOW_CTX_DAG_OWNER='***' AIRFLOW_CTX_DAG_ID='dag_32222222223' AIRFLOW_CTX_TASK_ID='transform_data_task' AIRFLOW_CTX_EXECUTION_DATE='2025-06-25T00:00:00+00:00' AIRFLOW_CTX_TRY_NUMBER='1' AIRFLOW_CTX_DAG_RUN_ID='scheduled__2025-06-25T00:00:00+00:00'
[2025-07-28T07:10:57.858+0000] {taskinstance.py:430} INFO - ::endgroup::
[2025-07-28T07:10:57.877+0000] {logging_mixin.py:188} INFO - Fetching data from Redis key: ***_data:dag_32222222223
[2025-07-28T07:10:57.899+0000] {logging_mixin.py:188} INFO - Applying algorithm 'aggregate_product_data' from module 'processor.transform.algos_1'
[2025-07-28T07:10:57.899+0000] {taskinstance.py:441} INFO - ::group::Post task execution logs
[2025-07-28T07:10:57.899+0000] {taskinstance.py:2905} ERROR - Task failed with exception
Traceback (most recent call last):
  File "/home/airflow/.local/lib/python3.12/site-packages/airflow/models/taskinstance.py", line 465, in _execute_task
    result = _execute_callable(context=context, **execute_callable_kwargs)
             ^^^^^^^^^^^^^^^^^^^^^^^^^^^^^^^^^^^^^^^^^^^^^^^^^^^^^^^^^^^^^
  File "/home/airflow/.local/lib/python3.12/site-packages/airflow/models/taskinstance.py", line 432, in _execute_callable
    return execute_callable(context=context, **execute_callable_kwargs)
           ^^^^^^^^^^^^^^^^^^^^^^^^^^^^^^^^^^^^^^^^^^^^^^^^^^^^^^^^^^^^
  File "/home/airflow/.local/lib/python3.12/site-packages/airflow/models/baseoperator.py", line 401, in wrapper
    return func(self, *args, **kwargs)
           ^^^^^^^^^^^^^^^^^^^^^^^^^^^
  File "/home/airflow/.local/lib/python3.12/site-packages/airflow/operators/python.py", line 235, in execute
    return_value = self.execute_callable()
                   ^^^^^^^^^^^^^^^^^^^^^^^
  File "/home/airflow/.local/lib/python3.12/site-packages/airflow/operators/python.py", line 252, in execute_callable
    return self.python_callable(*self.op_args, **self.op_kwargs)
           ^^^^^^^^^^^^^^^^^^^^^^^^^^^^^^^^^^^^^^^^^^^^^^^^^^^^^
  File "/opt/airflow/dags/processor/__init__.py", line 45, in transform_data
    processed_df = func(df, **algo_kwargs)
                              ^^^^^^^^^^^
NameError: name 'algo_kwargs' is not defined
[2025-07-28T07:10:57.910+0000] {taskinstance.py:1206} INFO - Marking task as FAILED. dag_id=dag_32222222223, task_id=transform_data_task, run_id=scheduled__2025-06-25T00:00:00+00:00, execution_date=20250625T000000, start_date=20250728T071057, end_date=20250728T071057
[2025-07-28T07:10:57.919+0000] {standard_task_runner.py:110} ERROR - Failed to execute job 21 for task transform_data_task (name 'algo_kwargs' is not defined; 7871)
[2025-07-28T07:10:57.954+0000] {local_task_job_runner.py:240} INFO - Task exited with return code 1
[2025-07-28T07:10:57.996+0000] {taskinstance.py:3503} INFO - 0 downstream tasks scheduled from follow-on schedule check
[2025-07-28T07:10:58.001+0000] {local_task_job_runner.py:222} INFO - ::endgroup::
