[2025-08-01T02:40:48.090+0000] {local_task_job_runner.py:120} INFO - ::group::Pre task execution logs
[2025-08-01T02:40:48.223+0000] {taskinstance.py:2076} INFO - Dependencies all met for dep_context=non-requeueable deps ti=<TaskInstance: dag_2222.transform_data_task scheduled__2025-06-29T00:00:00+00:00 [queued]>
[2025-08-01T02:40:48.231+0000] {taskinstance.py:2076} INFO - Dependencies all met for dep_context=requeueable deps ti=<TaskInstance: dag_2222.transform_data_task scheduled__2025-06-29T00:00:00+00:00 [queued]>
[2025-08-01T02:40:48.232+0000] {taskinstance.py:2306} INFO - Starting attempt 1 of 1
[2025-08-01T02:40:48.244+0000] {taskinstance.py:2330} INFO - Executing <Task(PythonOperator): transform_data_task> on 2025-06-29 00:00:00+00:00
[2025-08-01T02:40:48.250+0000] {logging_mixin.py:188} WARNING - /home/***/.local/lib/python3.12/site-packages/***/task/task_runner/standard_task_runner.py:61 DeprecationWarning: This process (pid=10319) is multi-threaded, use of fork() may lead to deadlocks in the child.
[2025-08-01T02:40:48.251+0000] {standard_task_runner.py:63} INFO - Started process 10324 to run task
[2025-08-01T02:40:48.251+0000] {standard_task_runner.py:90} INFO - Running: ['***', 'tasks', 'run', 'dag_2222', 'transform_data_task', 'scheduled__2025-06-29T00:00:00+00:00', '--job-id', '184', '--raw', '--subdir', 'DAGS_FOLDER/dag_generator.py', '--cfg-path', '/tmp/tmplo2lhbvp']
[2025-08-01T02:40:48.253+0000] {standard_task_runner.py:91} INFO - Job 184: Subtask transform_data_task
[2025-08-01T02:40:48.282+0000] {task_command.py:426} INFO - Running <TaskInstance: dag_2222.transform_data_task scheduled__2025-06-29T00:00:00+00:00 [running]> on host 14614e29d246
[2025-08-01T02:40:48.337+0000] {taskinstance.py:2648} INFO - Exporting env vars: AIRFLOW_CTX_DAG_OWNER='***' AIRFLOW_CTX_DAG_ID='dag_2222' AIRFLOW_CTX_TASK_ID='transform_data_task' AIRFLOW_CTX_EXECUTION_DATE='2025-06-29T00:00:00+00:00' AIRFLOW_CTX_TRY_NUMBER='1' AIRFLOW_CTX_DAG_RUN_ID='scheduled__2025-06-29T00:00:00+00:00'
[2025-08-01T02:40:48.337+0000] {taskinstance.py:430} INFO - ::endgroup::
[2025-08-01T02:40:48.346+0000] {__init__.py:92} INFO - 執行 transform_data (資料轉換層)
[2025-08-01T02:40:48.346+0000] {__init__.py:34} INFO - _get_upstream_output_path 上游任務: {'extract_data_task'}
[2025-08-01T02:40:48.346+0000] {__init__.py:50} INFO - 任務 'transform_data_task' 從單一上游 'extract_data_task' 拉取資料
[2025-08-01T02:40:48.352+0000] {__init__.py:52} INFO - 拉取到的 redis_key: ***_data:dag_2222.extract_data_task
[2025-08-01T02:40:48.354+0000] {__init__.py:152} ERROR - transform_data 發生例外: module 'processor.transform.algos_2' has no attribute 'aggregate_product_data'
[2025-08-01T02:40:48.354+0000] {taskinstance.py:441} INFO - ::group::Post task execution logs
[2025-08-01T02:40:48.354+0000] {taskinstance.py:2905} ERROR - Task failed with exception
Traceback (most recent call last):
  File "/home/airflow/.local/lib/python3.12/site-packages/airflow/models/taskinstance.py", line 465, in _execute_task
    result = _execute_callable(context=context, **execute_callable_kwargs)
             ^^^^^^^^^^^^^^^^^^^^^^^^^^^^^^^^^^^^^^^^^^^^^^^^^^^^^^^^^^^^^
  File "/home/airflow/.local/lib/python3.12/site-packages/airflow/models/taskinstance.py", line 432, in _execute_callable
    return execute_callable(context=context, **execute_callable_kwargs)
           ^^^^^^^^^^^^^^^^^^^^^^^^^^^^^^^^^^^^^^^^^^^^^^^^^^^^^^^^^^^^
  File "/home/airflow/.local/lib/python3.12/site-packages/airflow/models/baseoperator.py", line 401, in wrapper
    return func(self, *args, **kwargs)
           ^^^^^^^^^^^^^^^^^^^^^^^^^^^
  File "/home/airflow/.local/lib/python3.12/site-packages/airflow/operators/python.py", line 235, in execute
    return_value = self.execute_callable()
                   ^^^^^^^^^^^^^^^^^^^^^^^
  File "/home/airflow/.local/lib/python3.12/site-packages/airflow/operators/python.py", line 252, in execute_callable
    return self.python_callable(*self.op_args, **self.op_kwargs)
           ^^^^^^^^^^^^^^^^^^^^^^^^^^^^^^^^^^^^^^^^^^^^^^^^^^^^^
  File "/opt/airflow/dags/processor/__init__.py", line 114, in transform_data
    func = getattr(algo_module, algorithm_func)
           ^^^^^^^^^^^^^^^^^^^^^^^^^^^^^^^^^^^^
AttributeError: module 'processor.transform.algos_2' has no attribute 'aggregate_product_data'
[2025-08-01T02:40:48.363+0000] {taskinstance.py:1206} INFO - Marking task as FAILED. dag_id=dag_2222, task_id=transform_data_task, run_id=scheduled__2025-06-29T00:00:00+00:00, execution_date=20250629T000000, start_date=20250801T024048, end_date=20250801T024048
[2025-08-01T02:40:48.372+0000] {standard_task_runner.py:110} ERROR - Failed to execute job 184 for task transform_data_task (module 'processor.transform.algos_2' has no attribute 'aggregate_product_data'; 10324)
[2025-08-01T02:40:48.384+0000] {local_task_job_runner.py:240} INFO - Task exited with return code 1
[2025-08-01T02:40:48.399+0000] {taskinstance.py:3503} INFO - 0 downstream tasks scheduled from follow-on schedule check
[2025-08-01T02:40:48.403+0000] {local_task_job_runner.py:222} INFO - ::endgroup::
