[2025-07-30T08:15:04.063+0000] {local_task_job_runner.py:120} INFO - ::group::Pre task execution logs
[2025-07-30T08:15:04.083+0000] {taskinstance.py:2076} INFO - Dependencies all met for dep_context=non-requeueable deps ti=<TaskInstance: dag_rrrrrrrrrrrrrrrrr.extract_data_task scheduled__2025-06-25T00:00:00+00:00 [queued]>
[2025-07-30T08:15:04.089+0000] {taskinstance.py:2076} INFO - Dependencies all met for dep_context=requeueable deps ti=<TaskInstance: dag_rrrrrrrrrrrrrrrrr.extract_data_task scheduled__2025-06-25T00:00:00+00:00 [queued]>
[2025-07-30T08:15:04.090+0000] {taskinstance.py:2306} INFO - Starting attempt 1 of 1
[2025-07-30T08:15:04.101+0000] {taskinstance.py:2330} INFO - Executing <Task(PythonOperator): extract_data_task> on 2025-06-25 00:00:00+00:00
[2025-07-30T08:15:04.108+0000] {logging_mixin.py:188} WARNING - /home/***/.local/lib/python3.12/site-packages/***/task/task_runner/standard_task_runner.py:61 DeprecationWarning: This process (pid=5216) is multi-threaded, use of fork() may lead to deadlocks in the child.
[2025-07-30T08:15:04.109+0000] {standard_task_runner.py:63} INFO - Started process 5218 to run task
[2025-07-30T08:15:04.108+0000] {standard_task_runner.py:90} INFO - Running: ['***', 'tasks', 'run', 'dag_rrrrrrrrrrrrrrrrr', 'extract_data_task', 'scheduled__2025-06-25T00:00:00+00:00', '--job-id', '30', '--raw', '--subdir', 'DAGS_FOLDER/dag_generator_python.py', '--cfg-path', '/tmp/tmpfs8t4w4_']
[2025-07-30T08:15:04.110+0000] {standard_task_runner.py:91} INFO - Job 30: Subtask extract_data_task
[2025-07-30T08:15:04.262+0000] {task_command.py:426} INFO - Running <TaskInstance: dag_rrrrrrrrrrrrrrrrr.extract_data_task scheduled__2025-06-25T00:00:00+00:00 [running]> on host 14614e29d246
[2025-07-30T08:15:04.330+0000] {taskinstance.py:2648} INFO - Exporting env vars: AIRFLOW_CTX_DAG_OWNER='***' AIRFLOW_CTX_DAG_ID='dag_rrrrrrrrrrrrrrrrr' AIRFLOW_CTX_TASK_ID='extract_data_task' AIRFLOW_CTX_EXECUTION_DATE='2025-06-25T00:00:00+00:00' AIRFLOW_CTX_TRY_NUMBER='1' AIRFLOW_CTX_DAG_RUN_ID='scheduled__2025-06-25T00:00:00+00:00'
[2025-07-30T08:15:04.331+0000] {taskinstance.py:430} INFO - ::endgroup::
[2025-07-30T08:15:04.339+0000] {logging_mixin.py:188} INFO - 測試載入層
[2025-07-30T08:15:04.339+0000] {logging_mixin.py:188} INFO - Applying algorithm 'test_csv' from module 'processor.extract.readCSV'
[2025-07-30T08:15:04.340+0000] {logging_mixin.py:188} INFO - 3f2a4b93-b237-4545-bd50-5004d863567c.csv
[2025-07-30T08:15:04.352+0000] {logging_mixin.py:188} INFO - test11111111111111:***_data:set()
[2025-07-30T08:15:04.353+0000] {logging_mixin.py:188} INFO - Data stored in Redis key: ***_data:set()
[2025-07-30T08:15:04.360+0000] {taskinstance.py:441} INFO - ::group::Post task execution logs
[2025-07-30T08:15:04.360+0000] {taskinstance.py:2905} ERROR - Task failed with exception
Traceback (most recent call last):
  File "/home/airflow/.local/lib/python3.12/site-packages/sqlalchemy/engine/base.py", line 1910, in _execute_context
    self.dialect.do_execute(
  File "/home/airflow/.local/lib/python3.12/site-packages/sqlalchemy/engine/default.py", line 736, in do_execute
    cursor.execute(statement, parameters)
psycopg2.ProgrammingError: can't adapt type 'set'

The above exception was the direct cause of the following exception:

Traceback (most recent call last):
  File "/home/airflow/.local/lib/python3.12/site-packages/airflow/models/taskinstance.py", line 465, in _execute_task
    result = _execute_callable(context=context, **execute_callable_kwargs)
             ^^^^^^^^^^^^^^^^^^^^^^^^^^^^^^^^^^^^^^^^^^^^^^^^^^^^^^^^^^^^^
  File "/home/airflow/.local/lib/python3.12/site-packages/airflow/models/taskinstance.py", line 432, in _execute_callable
    return execute_callable(context=context, **execute_callable_kwargs)
           ^^^^^^^^^^^^^^^^^^^^^^^^^^^^^^^^^^^^^^^^^^^^^^^^^^^^^^^^^^^^
  File "/home/airflow/.local/lib/python3.12/site-packages/airflow/models/baseoperator.py", line 401, in wrapper
    return func(self, *args, **kwargs)
           ^^^^^^^^^^^^^^^^^^^^^^^^^^^
  File "/home/airflow/.local/lib/python3.12/site-packages/airflow/operators/python.py", line 235, in execute
    return_value = self.execute_callable()
                   ^^^^^^^^^^^^^^^^^^^^^^^
  File "/home/airflow/.local/lib/python3.12/site-packages/airflow/operators/python.py", line 252, in execute_callable
    return self.python_callable(*self.op_args, **self.op_kwargs)
           ^^^^^^^^^^^^^^^^^^^^^^^^^^^^^^^^^^^^^^^^^^^^^^^^^^^^^
  File "/opt/airflow/dags/processor/__init__.py", line 70, in extract_data
    ti.xcom_push(key=ti.task.upstream_task_ids, value=redis_key)
  File "/home/airflow/.local/lib/python3.12/site-packages/airflow/utils/session.py", line 79, in wrapper
    return func(*args, session=session, **kwargs)
           ^^^^^^^^^^^^^^^^^^^^^^^^^^^^^^^^^^^^^^
  File "/home/airflow/.local/lib/python3.12/site-packages/airflow/models/taskinstance.py", line 3197, in xcom_push
    XCom.set(
  File "/home/airflow/.local/lib/python3.12/site-packages/airflow/utils/session.py", line 76, in wrapper
    return func(*args, **kwargs)
           ^^^^^^^^^^^^^^^^^^^^^
  File "/home/airflow/.local/lib/python3.12/site-packages/airflow/models/xcom.py", line 256, in set
    session.execute(
  File "/home/airflow/.local/lib/python3.12/site-packages/sqlalchemy/orm/session.py", line 1717, in execute
    result = conn._execute_20(statement, params or {}, execution_options)
             ^^^^^^^^^^^^^^^^^^^^^^^^^^^^^^^^^^^^^^^^^^^^^^^^^^^^^^^^^^^^
  File "/home/airflow/.local/lib/python3.12/site-packages/sqlalchemy/engine/base.py", line 1710, in _execute_20
    return meth(self, args_10style, kwargs_10style, execution_options)
           ^^^^^^^^^^^^^^^^^^^^^^^^^^^^^^^^^^^^^^^^^^^^^^^^^^^^^^^^^^^
  File "/home/airflow/.local/lib/python3.12/site-packages/sqlalchemy/sql/elements.py", line 334, in _execute_on_connection
    return connection._execute_clauseelement(
           ^^^^^^^^^^^^^^^^^^^^^^^^^^^^^^^^^^
  File "/home/airflow/.local/lib/python3.12/site-packages/sqlalchemy/engine/base.py", line 1577, in _execute_clauseelement
    ret = self._execute_context(
          ^^^^^^^^^^^^^^^^^^^^^^
  File "/home/airflow/.local/lib/python3.12/site-packages/sqlalchemy/engine/base.py", line 1953, in _execute_context
    self._handle_dbapi_exception(
  File "/home/airflow/.local/lib/python3.12/site-packages/sqlalchemy/engine/base.py", line 2134, in _handle_dbapi_exception
    util.raise_(
  File "/home/airflow/.local/lib/python3.12/site-packages/sqlalchemy/util/compat.py", line 211, in raise_
    raise exception
  File "/home/airflow/.local/lib/python3.12/site-packages/sqlalchemy/engine/base.py", line 1910, in _execute_context
    self.dialect.do_execute(
  File "/home/airflow/.local/lib/python3.12/site-packages/sqlalchemy/engine/default.py", line 736, in do_execute
    cursor.execute(statement, parameters)
sqlalchemy.exc.ProgrammingError: (psycopg2.ProgrammingError) can't adapt type 'set'
[SQL: DELETE FROM xcom WHERE xcom.key = %(key_1)s AND xcom.run_id = %(run_id_1)s AND xcom.task_id = %(task_id_1)s AND xcom.dag_id = %(dag_id_1)s AND xcom.map_index = %(map_index_1)s]
[parameters: {'key_1': set(), 'run_id_1': 'scheduled__2025-06-25T00:00:00+00:00', 'task_id_1': 'extract_data_task', 'dag_id_1': 'dag_rrrrrrrrrrrrrrrrr', 'map_index_1': -1}]
(Background on this error at: https://sqlalche.me/e/14/f405)
[2025-07-30T08:15:04.371+0000] {taskinstance.py:1206} INFO - Marking task as FAILED. dag_id=dag_rrrrrrrrrrrrrrrrr, task_id=extract_data_task, run_id=scheduled__2025-06-25T00:00:00+00:00, execution_date=20250625T000000, start_date=20250730T081504, end_date=20250730T081504
[2025-07-30T08:15:04.378+0000] {standard_task_runner.py:110} ERROR - Failed to execute job 30 for task extract_data_task ((psycopg2.ProgrammingError) can't adapt type 'set'
[SQL: DELETE FROM xcom WHERE xcom.key = %(key_1)s AND xcom.run_id = %(run_id_1)s AND xcom.task_id = %(task_id_1)s AND xcom.dag_id = %(dag_id_1)s AND xcom.map_index = %(map_index_1)s]
[parameters: {'key_1': set(), 'run_id_1': 'scheduled__2025-06-25T00:00:00+00:00', 'task_id_1': 'extract_data_task', 'dag_id_1': 'dag_rrrrrrrrrrrrrrrrr', 'map_index_1': -1}]
(Background on this error at: https://sqlalche.me/e/14/f405); 5218)
[2025-07-30T08:15:04.403+0000] {local_task_job_runner.py:240} INFO - Task exited with return code 1
[2025-07-30T08:15:04.635+0000] {taskinstance.py:3503} INFO - 0 downstream tasks scheduled from follow-on schedule check
[2025-07-30T08:15:04.644+0000] {local_task_job_runner.py:222} INFO - ::endgroup::
