[2025-07-31T02:14:26.372+0000] {local_task_job_runner.py:120} INFO - ::group::Pre task execution logs
[2025-07-31T02:14:26.478+0000] {taskinstance.py:2076} INFO - Dependencies all met for dep_context=non-requeueable deps ti=<TaskInstance: dag_111111ddddwww6ffsfsg.transform_data_task scheduled__2025-06-25T00:00:00+00:00 [queued]>
[2025-07-31T02:14:26.483+0000] {taskinstance.py:2076} INFO - Dependencies all met for dep_context=requeueable deps ti=<TaskInstance: dag_111111ddddwww6ffsfsg.transform_data_task scheduled__2025-06-25T00:00:00+00:00 [queued]>
[2025-07-31T02:14:26.484+0000] {taskinstance.py:2306} INFO - Starting attempt 1 of 1
[2025-07-31T02:14:26.492+0000] {taskinstance.py:2330} INFO - Executing <Task(PythonOperator): transform_data_task> on 2025-06-25 00:00:00+00:00
[2025-07-31T02:14:26.498+0000] {logging_mixin.py:188} WARNING - /home/***/.local/lib/python3.12/site-packages/***/task/task_runner/standard_task_runner.py:61 DeprecationWarning: This process (pid=7909) is multi-threaded, use of fork() may lead to deadlocks in the child.
[2025-07-31T02:14:26.498+0000] {standard_task_runner.py:63} INFO - Started process 7912 to run task
[2025-07-31T02:14:26.498+0000] {standard_task_runner.py:90} INFO - Running: ['***', 'tasks', 'run', 'dag_111111ddddwww6ffsfsg', 'transform_data_task', 'scheduled__2025-06-25T00:00:00+00:00', '--job-id', '145', '--raw', '--subdir', 'DAGS_FOLDER/dag_generator_python.py', '--cfg-path', '/tmp/tmpr7qqk9m0']
[2025-07-31T02:14:26.499+0000] {standard_task_runner.py:91} INFO - Job 145: Subtask transform_data_task
[2025-07-31T02:14:26.536+0000] {task_command.py:426} INFO - Running <TaskInstance: dag_111111ddddwww6ffsfsg.transform_data_task scheduled__2025-06-25T00:00:00+00:00 [running]> on host 14614e29d246
[2025-07-31T02:14:26.593+0000] {taskinstance.py:2648} INFO - Exporting env vars: AIRFLOW_CTX_DAG_OWNER='***' AIRFLOW_CTX_DAG_ID='dag_111111ddddwww6ffsfsg' AIRFLOW_CTX_TASK_ID='transform_data_task' AIRFLOW_CTX_EXECUTION_DATE='2025-06-25T00:00:00+00:00' AIRFLOW_CTX_TRY_NUMBER='1' AIRFLOW_CTX_DAG_RUN_ID='scheduled__2025-06-25T00:00:00+00:00'
[2025-07-31T02:14:26.594+0000] {taskinstance.py:430} INFO - ::endgroup::
[2025-07-31T02:14:26.603+0000] {__init__.py:92} INFO - 執行 transform_data (資料轉換層)
[2025-07-31T02:14:26.603+0000] {__init__.py:34} INFO - _get_upstream_output_path 上游任務: {'extract_data_task'}
[2025-07-31T02:14:26.603+0000] {__init__.py:50} INFO - 任務 'transform_data_task' 從單一上游 'extract_data_task' 拉取資料
[2025-07-31T02:14:26.610+0000] {__init__.py:52} INFO - 拉取到的 redis_key: ***_data:dag_111111ddddwww6ffsfsg.extract_data_task
[2025-07-31T02:14:26.612+0000] {__init__.py:115} INFO - 呼叫演算法 'add_test' 來自模組 'processor.transform.algos_2'
[2025-07-31T02:14:26.613+0000] {__init__.py:152} ERROR - transform_data 發生例外: name 'logger' is not defined
[2025-07-31T02:14:26.613+0000] {taskinstance.py:441} INFO - ::group::Post task execution logs
[2025-07-31T02:14:26.613+0000] {taskinstance.py:2905} ERROR - Task failed with exception
Traceback (most recent call last):
  File "/opt/airflow/dags/processor/transform/algos_2.py", line 11, in add_test
    logger.info("資料處理完成")
    ^^^^^^
NameError: name 'logger' is not defined

During handling of the above exception, another exception occurred:

Traceback (most recent call last):
  File "/home/airflow/.local/lib/python3.12/site-packages/airflow/models/taskinstance.py", line 465, in _execute_task
    result = _execute_callable(context=context, **execute_callable_kwargs)
             ^^^^^^^^^^^^^^^^^^^^^^^^^^^^^^^^^^^^^^^^^^^^^^^^^^^^^^^^^^^^^
  File "/home/airflow/.local/lib/python3.12/site-packages/airflow/models/taskinstance.py", line 432, in _execute_callable
    return execute_callable(context=context, **execute_callable_kwargs)
           ^^^^^^^^^^^^^^^^^^^^^^^^^^^^^^^^^^^^^^^^^^^^^^^^^^^^^^^^^^^^
  File "/home/airflow/.local/lib/python3.12/site-packages/airflow/models/baseoperator.py", line 401, in wrapper
    return func(self, *args, **kwargs)
           ^^^^^^^^^^^^^^^^^^^^^^^^^^^
  File "/home/airflow/.local/lib/python3.12/site-packages/airflow/operators/python.py", line 235, in execute
    return_value = self.execute_callable()
                   ^^^^^^^^^^^^^^^^^^^^^^^
  File "/home/airflow/.local/lib/python3.12/site-packages/airflow/operators/python.py", line 252, in execute_callable
    return self.python_callable(*self.op_args, **self.op_kwargs)
           ^^^^^^^^^^^^^^^^^^^^^^^^^^^^^^^^^^^^^^^^^^^^^^^^^^^^^
  File "/opt/airflow/dags/processor/__init__.py", line 117, in transform_data
    processed_data = func(data_list, **algo_kwargs)
                     ^^^^^^^^^^^^^^^^^^^^^^^^^^^^^^
  File "/opt/airflow/dags/processor/transform/algos_2.py", line 14, in add_test
    logger.error(f"extract_data 發生例外: {e}")
    ^^^^^^
NameError: name 'logger' is not defined
[2025-07-31T02:14:26.620+0000] {taskinstance.py:1206} INFO - Marking task as FAILED. dag_id=dag_111111ddddwww6ffsfsg, task_id=transform_data_task, run_id=scheduled__2025-06-25T00:00:00+00:00, execution_date=20250625T000000, start_date=20250731T021426, end_date=20250731T021426
[2025-07-31T02:14:26.627+0000] {standard_task_runner.py:110} ERROR - Failed to execute job 145 for task transform_data_task (name 'logger' is not defined; 7912)
[2025-07-31T02:14:26.671+0000] {local_task_job_runner.py:240} INFO - Task exited with return code 1
[2025-07-31T02:14:26.686+0000] {taskinstance.py:3503} INFO - 0 downstream tasks scheduled from follow-on schedule check
[2025-07-31T02:14:26.689+0000] {local_task_job_runner.py:222} INFO - ::endgroup::
